Workbook

Sheet Sheet1
A3: Row Labels | B3: Average of avg_monthly_revenue
A4: Fatigued | B4: 457.5625
A5: Healthy | B5: 441.74189
A6: Grand Total | B6: 442.0583

Sheet User-Level Revenue & Fatigue Ta
A1: fatigued | B1: Yes | D1: user_id | E1: user_fatigue_status | F1: total_revenue | G1: avg_monthly_revenue
D2: U001 | E2: =IF(COUNTIFS(subscriptions!$A:$A, D2, subscriptions!$M:$M, "Yes")>0, "Fatigued", "Healthy") -> Healthy | F2: 1497 | G2: 499
A3: Row Labels | B3: Count of fatigued | D3: U002 | E3: =IF(COUNTIFS(subscriptions!$A:$A, D3, subscriptions!$M:$M, "Yes")>0, "Fatigued", "Healthy") -> Fatigued | F3: 1996 | G3: 499
A4: U002 | B4: 1 | D4: U003 | E4: =IF(COUNTIFS(subscriptions!$A:$A, D4, subscriptions!$M:$M, "Yes")>0, "Fatigued", "Healthy") -> Healthy | F4: 2495 | G4: 499
A5: U014 | B5: 1 | D5: U004 | E5: =IF(COUNTIFS(subscriptions!$A:$A, D5, subscriptions!$M:$M, "Yes")>0, "Fatigued", "Healthy") -> Healthy | F5: 998 | G5: 499
A6: U019 | B6: 1 | D6: U005 | E6: =IF(COUNTIFS(subscriptions!$A:$A, D6, subscriptions!$M:$M, "Yes")>0, "Fatigued", "Healthy") -> Healthy | F6: 1297 | G6: 432.33
A7: U042 | B7: 1 | D7: U006 | E7: =IF(COUNTIFS(subscriptions!$A:$A, D7, subscriptions!$M:$M, "Yes")>0, "Fatigued", "Healthy") -> Healthy | F7: 1996 | G7: 499
A8: Grand Total | B8: 4 | D8: U007 | E8: =IF(COUNTIFS(subscriptions!$A:$A, D8, subscriptions!$M:$M, "Yes")>0, "Fatigued", "Healthy") -> Healthy | F8: 2495 | G8: 499
D9: U008 | E9: =IF(COUNTIFS(subscriptions!$A:$A, D9, subscriptions!$M:$M, "Yes")>0, "Fatigued", "Healthy") -> Healthy | F9: 998 | G9: 499
D10: U009 | E10: =IF(COUNTIFS(subscriptions!$A:$A, D10, subscriptions!$M:$M, "Yes")>0, "Fatigued", "Healthy") -> Healthy | F10: 1497 | G10: 499
D11: U010 | E11: =IF(COUNTIFS(subscriptions!$A:$A, D11, subscriptions!$M:$M, "Yes")>0, "Fatigued", "Healthy") -> Healthy | F11: 1796 | G11: 449
D12: U011 | E12: =IF(COUNTIFS(subscriptions!$A:$A, D12, subscriptions!$M:$M, "Yes")>0, "Fatigued", "Healthy") -> Healthy | F12: 2495 | G12: 499
D13: U012 | E13: =IF(COUNTIFS(subscriptions!$A:$A, D13, subscriptions!$M:$M, "Yes")>0, "Fatigued", "Healthy") -> Healthy | F13: 998 | G13: 499
D14: U013 | E14: =IF(COUNTIFS(subscriptions!$A:$A, D14, subscriptions!$M:$M, "Yes")>0, "Fatigued", "Healthy") -> Healthy | F14: 1497 | G14: 499
D15: U014 | E15: =IF(COUNTIFS(subscriptions!$A:$A, D15, subscriptions!$M:$M, "Yes")>0, "Fatigued", "Healthy") -> Fatigued | F15: 1996 | G15: 499
D16: U015 | E16: =IF(COUNTIFS(subscriptions!$A:$A, D16, subscriptions!$M:$M, "Yes")>0, "Fatigued", "Healthy") -> Healthy | F16: 2295 | G16: 459
D17: U016 | E17: =IF(COUNTIFS(subscriptions!$A:$A, D17, subscriptions!$M:$M, "Yes")>0, "Fatigued", "Healthy") -> Healthy | F17: 998 | G17: 499
D18: U017 | E18: =IF(COUNTIFS(subscriptions!$A:$A, D18, subscriptions!$M:$M, "Yes")>0, "Fatigued", "Healthy") -> Healthy | F18: 1497 | G18: 499
D19: U018 | E19: =IF(COUNTIFS(subscriptions!$A:$A, D19, subscriptions!$M:$M, "Yes")>0, "Fatigued", "Healthy") -> Healthy | F19: 1996 | G19: 499
D20: U019 | E20: =IF(COUNTIFS(subscriptions!$A:$A, D20, subscriptions!$M:$M, "Yes")>0, "Fatigued", "Healthy") -> Fatigued | F20: 2495 | G20: 499
... D201: U200 | E201: =IF(COUNTIFS(subscriptions!$A:$A, D201, subscriptions!$M:$M, "Yes")>0, "Fatigued", "Healthy") -> Healthy | F201: 3999 | G201: 333.25

Sheet subscriptions
A1: user_id | B1: plan_type | C1: start_date | D1: renewal_date | E1: cancel_date | F1: price | G1: cohort | H1: push_count | I1: actual_pushcount | J1: email_count | K1: actual_emailcount | L1: engagement_level | M1: fatigued
A2: U001 | B2: Monthly | C2: 45296 | D2: 45327 | F2: 499 | G2: 45292 | H2: 1 | I2: =IF(H2<=1,"Low",IF(H2<=4,"Medium","High")) -> Low | J2: 3 | K2: =IF(J2<=1,"Low",IF(J2=2,"Medium","High")) -> High | L2: =IF(OR(I2="High",K2="High"),"High", IF(OR(I2="Medium",K2="Medium"),"Medium", "Low")) -> High | M2: =IF(AND(TRIM(I2)="High",TRIM(L2)="Low"),"Yes","No") -> No
A3: U002 | B3: Monthly | C3: 45297 | D3: 45328 | E3: 45319 | F3: 499 | G3: 45292 | H3: 7 | I3: =IF(H3<=1,"Low",IF(H3<=4,"Medium","High")) -> High | J3: 5 | K3: =IF(J3<=1,"Low",IF(J3=2,"Medium","High")) -> High | L3: low | M3: =IF(AND(TRIM(I3)="High",TRIM(L3)="Low"),"Yes","No") -> Yes
A4: U003 | B4: Annual | C4: 45298 | D4: 45664 | F4: 3999 | G4: 45292 | H4: 38 | I4: =IF(H4<=1,"Low",IF(H4<=4,"Medium","High")) -> High | J4: 15 | K4: =IF(J4<=1,"Low",IF(J4=2,"Medium","High")) -> High | L4: =IF(OR(I4="High",K4="High"),"High", IF(OR(I4="Medium",K4="Medium"),"Medium", "Low")) -> High | M4: =IF(AND(TRIM(I4)="High",TRIM(L4)="Low"),"Yes","No") -> No
A5: U004 | B5: Monthly | C5: 45299 | D5: 45330 | F5: 499 | G5: 45292 | H5: 0 | I5: =IF(H5<=1,"Low",IF(H5<=4,"Medium","High")) -> Low | J5: 0 | K5: =IF(J5<=1,"Low",IF(J5=2,"Medium","High")) -> Low | L5: =IF(OR(I5="High",K5="High"),"High", IF(OR(I5="Medium",K5="Medium"),"Medium", "Low")) -> Low | M5: =IF(AND(TRIM(I5)="High",TRIM(L5)="Low"),"Yes","No") -> No
A6: U005 | B6: Monthly | C6: 45300 | D6: 45331 | E6: 45321 | F6: 499 | G6: 45292 | H6: 43 | I6: =IF(H6<=1,"Low",IF(H6<=4,"Medium","High")) -> High | J6: 15 | K6: =IF(J6<=1,"Low",IF(J6=2,"Medium","High")) -> High | L6: =IF(OR(I6="High",K6="High"),"High", IF(OR(I6="Medium",K6="Medium"),"Medium", "Low")) -> High | M6: =IF(AND(TRIM(I6)="High",TRIM(L6)="Low"),"Yes","No") -> No
A7: U006 | B7: Annual | C7: 45301 | D7: 45667 | F7: 3999 | G7: 45292 | H7: 6 | I7: =IF(H7<=1,"Low",IF(H7<=4,"Medium","High")) -> High | J7: 7 | K7: =IF(J7<=1,"Low",IF(J7=2,"Medium","High")) -> High | L7: =IF(OR(I7="High",K7="High"),"High", IF(OR(I7="Medium",K7="Medium"),"Medium", "Low")) -> High | M7: =IF(AND(TRIM(I7)="High",TRIM(L7)="Low"),"Yes","No") -> No
A8: U007 | B8: Monthly | C8: 45302 | D8: 45333 | F8: 499 | G8: 45292 | H8: 5 | I8: =IF(H8<=1,"Low",IF(H8<=4,"Medium","High")) -> High | J8: 6 | K8: =IF(J8<=1,"Low",IF(J8=2,"Medium","High")) -> High | L8: =IF(OR(I8="High",K8="High"),"High", IF(OR(I8="Medium",K8="Medium"),"Medium", "Low")) -> High | M8: =IF(AND(TRIM(I8)="High",TRIM(L8)="Low"),"Yes","No") -> No
A9: U008 | B9: Monthly | C9: 45303 | D9: 45334 | E9: 45323 | F9: 499 | G9: 45292 | H9: 34 | I9: =IF(H9<=1,"Low",IF(H9<=4,"Medium","High")) -> High | J9: 16 | K9: =IF(J9<=1,"Low",IF(J9=2,"Medium","High")) -> High | L9: =IF(OR(I9="High",K9="High"),"High", IF(OR(I9="Medium",K9="Medium"),"Medium", "Low")) -> High | M9: =IF(AND(TRIM(I9)="High",TRIM(L9)="Low"),"Yes","No") -> No
A10: U009 | B10: Annual | C10: 45304 | D10: 45670 | F10: 3999 | G10: 45292 | H10: 29 | I10: =IF(H10<=1,"Low",IF(H10<=4,"Medium","High")) -> High | J10: 13 | K10: =IF(J10<=1,"Low",IF(J10=2,"Medium","High")) -> High | L10: =IF(OR(I10="High",K10="High"),"High", IF(OR(I10="Medium",K10="Medium"),"Medium", "Low")) -> High | M10: =IF(AND(TRIM(I10)="High",TRIM(L10)="Low"),"Yes","No") -> No
A11: U010 | B11: Monthly | C11: 45305 | D11: 45336 | F11: 499 | G11: 45292 | H11: 40 | I11: =IF(H11<=1,"Low",IF(H11<=4,"Medium","High")) -> High | J11: 13 | K11: =IF(J11<=1,"Low",IF(J11=2,"Medium","High")) -> High | L11: =IF(OR(I11="High",K11="High"),"High", IF(OR(I11="Medium",K11="Medium"),"Medium", "Low")) -> High | M11: =IF(AND(TRIM(I11)="High",TRIM(L11)="Low"),"Yes","No") -> No
A12: U011 | B12: Monthly | C12: 45306 | D12: 45337 | E12: 45327 | F12: 499 | G12: 45292 | H12: 4 | I12: =IF(H12<=1,"Low",IF(H12<=4,"Medium","High")) -> Medium | J12: 4 | K12: =IF(J12<=1,"Low",IF(J12=2,"Medium","High")) -> High | L12: =IF(OR(I12="High",K12="High"),"High", IF(OR(I12="Medium",K12="Medium"),"Medium", "Low")) -> High | M12: =IF(AND(TRIM(I12)="High",TRIM(L12)="Low"),"Yes","No") -> No
A13: U012 | B13: Annual | C13: 45307 | D13: 45673 | F13: 3999 | G13: 45292 | H13: 1 | I13: =IF(H13<=1,"Low",IF(H13<=4,"Medium","High")) -> Low | J13: 2 | K13: =IF(J13<=1,"Low",IF(J13=2,"Medium","High")) -> Medium | L13: =IF(OR(I13="High",K13="High"),"High", IF(OR(I13="Medium",K13="Medium"),"Medium", "Low")) -> Medium | M13: =IF(AND(TRIM(I13)="High",TRIM(L13)="Low"),"Yes","No") -> No
A14: U013 | B14: Monthly | C14: 45308 | D14: 45339 | F14: 499 | G14: 45292 | H14: 39 | I14: =IF(H14<=1,"Low",IF(H14<=4,"Medium","High")) -> High | J14: 12 | K14: =IF(J14<=1,"Low",IF(J14=2,"Medium","High")) -> High | L14: =IF(OR(I14="High",K14="High"),"High", IF(OR(I14="Medium",K14="Medium"),"Medium", "Low")) -> High | M14: =IF(AND(TRIM(I14)="High",TRIM(L14)="Low"),"Yes","No") -> No
A15: U014 | B15: Monthly | C15: 45309 | D15: 45340 | E15: 45332 | F15: 499 | G15: 45292 | H15: 33 | I15: =IF(H15<=1,"Low",IF(H15<=4,"Medium","High")) -> High | J15: 13 | K15: =IF(J15<=1,"Low",IF(J15=2,"Medium","High")) -> High | L15: low | M15: =IF(AND(TRIM(I15)="High",TRIM(L15)="Low"),"Yes","No") -> Yes
A16: U015 | B16: Annual | C16: 45310 | D16: 45676 | F16: 3999 | G16: 45292 | H16: 43 | I16: =IF(H16<=1,"Low",IF(H16<=4,"Medium","High")) -> High | J16: 18 | K16: =IF(J16<=1,"Low",IF(J16=2,"Medium","High")) -> High | L16: =IF(OR(I16="High",K16="High"),"High", IF(OR(I16="Medium",K16="Medium"),"Medium", "Low")) -> High | M16: =IF(AND(TRIM(I16)="High",TRIM(L16)="Low"),"Yes","No") -> No
A17: U016 | B17: Monthly | C17: 45311 | D17: 45342 | F17: 499 | G17: 45292 | H17: 2 | I17: =IF(H17<=1,"Low",IF(H17<=4,"Medium","High")) -> Medium | J17: 10 | K17: =IF(J17<=1,"Low",IF(J17=2,"Medium","High")) -> High | L17: =IF(OR(I17="High",K17="High"),"High", IF(OR(I17="Medium",K17="Medium"),"Medium", "Low")) -> High | M17: =IF(AND(TRIM(I17)="High",TRIM(L17)="Low"),"Yes","No") -> No
A18: U017 | B18: Monthly | C18: 45312 | D18: 45343 | E18: 45334 | F18: 499 | G18: 45292 | H18: 6 | I18: =IF(H18<=1,"Low",IF(H18<=4,"Medium","High")) -> High | J18: 9 | K18: =IF(J18<=1,"Low",IF(J18=2,"Medium","High")) -> High | L18: =IF(OR(I18="High",K18="High"),"High", IF(OR(I18="Medium",K18="Medium"),"Medium", "Low")) -> High | M18: =IF(AND(TRIM(I18)="High",TRIM(L18)="Low"),"Yes","No") -> No
A19: U018 | B19: Annual | C19: 45313 | D19: 45679 | F19: 3999 | G19: 45292 | H19: 42 | I19: =IF(H19<=1,"Low",IF(H19<=4,"Medium","High")) -> High | J19: 11 | K19: =IF(J19<=1,"Low",IF(J19=2,"Medium","High")) -> High | L19: =IF(OR(I19="High",K19="High"),"High", IF(OR(I19="Medium",K19="Medium"),"Medium", "Low")) -> High | M19: =IF(AND(TRIM(I19)="High",TRIM(L19)="Low"),"Yes","No") -> No
A20: U019 | B20: Monthly | C20: 45314 | D20: 45345 | F20: 499 | G20: 45292 | H20: 27 | I20: =IF(H20<=1,"Low",IF(H20<=4,"Medium","High")) -> High | J20: 8 | K20: =IF(J20<=1,"Low",IF(J20=2,"Medium","High")) -> High | L20: low | M20: =IF(AND(TRIM(I20)="High",TRIM(L20)="Low"),"Yes","No") -> Yes
A21: U020 | B21: Monthly | C21: 45315 | D21: 45346 | E21: 45337 | F21: 499 | G21: 45292 | H21: 36 | I21: =IF(H21<=1,"Low",IF(H21<=4,"Medium","High")) -> High | J21: 14 | K21: =IF(J21<=1,"Low",IF(J21=2,"Medium","High")) -> High | L21: =IF(OR(I21="High",K21="High"),"High", IF(OR(I21="Medium",K21="Medium"),"Medium", "Low")) -> High | M21: =IF(AND(TRIM(I21)="High",TRIM(L21)="Low"),"Yes","No") -> No
A22: U021 | B22: Annual | C22: 45316 | D22: 45682 | F22: 3999 | G22: 45292 | H22: 2 | I22: =IF(H22<=1,"Low",IF(H22<=4,"Medium","High")) -> Medium | J22: 6 | K22: =IF(J22<=1,"Low",IF(J22=2,"Medium","High")) -> High | L22: =IF(OR(I22="High",K22="High"),"High", IF(OR(I22="Medium",K22="Medium"),"Medium", "Low")) -> High | M22: =IF(AND(TRIM(I22)="High",TRIM(L22)="Low"),"Yes","No") -> No
A23: U022 | B23: Monthly | C23: 45317 | D23: 45348 | F23: 499 | G23: 45292 | H23: 7 | I23: =IF(H23<=1,"Low",IF(H23<=4,"Medium","High")) -> High | J23: 7 | K23: =IF(J23<=1,"Low",IF(J23=2,"Medium","High")) -> High | L23: =IF(OR(I23="High",K23="High"),"High", IF(OR(I23="Medium",K23="Medium"),"Medium", "Low")) -> High | M23: =IF(AND(TRIM(I23)="High",TRIM(L23)="Low"),"Yes","No") -> No
A24: U023 | B24: Monthly | C24: 45318 | D24: 45349 | E24: 45340 | F24: 499 | G24: 45292 | H24: 40 | I24: =IF(H24<=1,"Low",IF(H24<=4,"Medium","High")) -> High | J24: 15 | K24: =IF(J24<=1,"Low",IF(J24=2,"Medium","High")) -> High | L24: =IF(OR(I24="High",K24="High"),"High", IF(OR(I24="Medium",K24="Medium"),"Medium", "Low")) -> High | M24: =IF(AND(TRIM(I24)="High",TRIM(L24)="Low"),"Yes","No") -> No
A25: U024 | B25: Annual | C25: 45319 | D25: 45685 | F25: 3999 | G25: 45292 | H25: 29 | I25: =IF(H25<=1,"Low",IF(H25<=4,"Medium","High")) -> High | J25: 9 | K25: =IF(J25<=1,"Low",IF(J25=2,"Medium","High")) -> High | L25: =IF(OR(I25="High",K25="High"),"High", IF(OR(I25="Medium",K25="Medium"),"Medium", "Low")) -> High | M25: =IF(AND(TRIM(I25)="High",TRIM(L25)="Low"),"Yes","No") -> No
A26: U025 | B26: Monthly | C26: 45320 | D26: 45351 | F26: 499 | G26: 45292 | H26: 34 | I26: =IF(H26<=1,"Low",IF(H26<=4,"Medium","High")) -> High | J26: 12 | K26: =IF(J26<=1,"Low",IF(J26=2,"Medium","High")) -> High | L26: =IF(OR(I26="High",K26="High"),"High", IF(OR(I26="Medium",K26="Medium"),"Medium", "Low")) -> High | M26: =IF(AND(TRIM(I26)="High",TRIM(L26)="Low"),"Yes","No") -> No
A27: U026 | B27: Monthly | C27: 45321 | D27: 45352 | E27: 45342 | F27: 499 | G27: 45292 | H27: 5 | I27: =IF(H27<=1,"Low",IF(H27<=4,"Medium","High")) -> High | J27: 13 | K27: =IF(J27<=1,"Low",IF(J27=2,"Medium","High")) -> High | L27: =IF(OR(I27="High",K27="High"),"High", IF(OR(I27="Medium",K27="Medium"),"Medium", "Low")) -> High | M27: =IF(AND(TRIM(I27)="High",TRIM(L27)="Low"),"Yes","No") -> No
A28: U027 | B28: Annual | C28: 45323 | D28: 45689 | F28: 3999 | G28: 45323 | H28: 6 | I28: =IF(H28<=1,"Low",IF(H28<=4,"Medium","High")) -> High | J28: 11 | K28: =IF(J28<=1,"Low",IF(J28=2,"Medium","High")) -> High | L28: =IF(OR(I28="High",K28="High"),"High", IF(OR(I28="Medium",K28="Medium"),"Medium", "Low")) -> High | M28: =IF(AND(TRIM(I28)="High",TRIM(L28)="Low"),"Yes","No") -> No
A29: U028 | B29: Monthly | C29: 45324 | D29: 45353 | F29: 499 | G29: 45323 | H29: 41 | I29: =IF(H29<=1,"Low",IF(H29<=4,"Medium","High")) -> High | J29: 10 | K29: =IF(J29<=1,"Low",IF(J29=2,"Medium","High")) -> High | L29: =IF(OR(I29="High",K29="High"),"High", IF(OR(I29="Medium",K29="Medium"),"Medium", "Low")) -> High | M29: =IF(AND(TRIM(I29)="High",TRIM(L29)="Low"),"Yes","No") -> No
A30: U029 | B30: Monthly | C30: 45325 | D30: 45354 | E30: 45344 | F30: 499 | G30: 45323 | H30: 28 | I30: =IF(H30<=1,"Low",IF(H30<=4,"Medium","High")) -> High | J30: 14 | K30: =IF(J30<=1,"Low",IF(J30=2,"Medium","High")) -> High | L30: =IF(OR(I30="High",K30="High"),"High", IF(OR(I30="Medium",K30="Medium"),"Medium", "Low")) -> High | M30: =IF(AND(TRIM(I30)="High",TRIM(L30)="Low"),"Yes","No") -> No
A31: U030 | B31: Annual | C31: 45326 | D31: 45692 | F31: 3999 | G31: 45323 | H31: 37 | I31: =IF(H31<=1,"Low",IF(H31<=4,"Medium","High")) -> High | J31: 16 | K31: =IF(J31<=1,"Low",IF(J31=2,"Medium","High")) -> High | L31: =IF(OR(I31="High",K31="High"),"High", IF(OR(I31="Medium",K31="Medium"),"Medium", "Low")) -> High | M31: =IF(AND(TRIM(I31)="High",TRIM(L31)="Low"),"Yes","No") -> No
A32: U031 | B32: Monthly | C32: 45327 | D32: 45356 | F32: 499 | G32: 45323 | H32: 3 | I32: =IF(H32<=1,"Low",IF(H32<=4,"Medium","High")) -> Medium | J32: 8 | K32: =IF(J32<=1,"Low",IF(J32=2,"Medium","High")) -> High | L32: =IF(OR(I32="High",K32="High"),"High", IF(OR(I32="Medium",K32="Medium"),"Medium", "Low")) -> High | M32: =IF(AND(TRIM(I32)="High",TRIM(L32)="Low"),"Yes","No") -> No
A33: U032 | B33: Monthly | C33: 45328 | D33: 45357 | E33: 45347 | F33: 499 | G33: 45323 | H33: 5 | I33: =IF(H33<=1,"Low",IF(H33<=4,"Medium","High")) -> High | J33: 9 | K33: =IF(J33<=1,"Low",IF(J33=2,"Medium","High")) -> High | L33: =IF(OR(I33="High",K33="High"),"High", IF(OR(I33="Medium",K33="Medium"),"Medium", "Low")) -> High | M33: =IF(AND(TRIM(I33)="High",TRIM(L33)="Low"),"Yes","No") -> No
A34: U033 | B34: Annual | C34: 45329 | D34: 45695 | F34: 3999 | G34: 45323 | H34: 38 | I34: =IF(H34<=1,"Low",IF(H34<=4,"Medium","High")) -> High | J34: 12 | K34: =IF(J34<=1,"Low",IF(J34=2,"Medium","High")) -> High | L34: =IF(OR(I34="High",K34="High"),"High", IF(OR(I34="Medium",K34="Medium"),"Medium", "Low")) -> High | M34: =IF(AND(TRIM(I34)="High",TRIM(L34)="Low"),"Yes","No") -> No
A35: U034 | B35: Monthly | C35: 45330 | D35: 45359 | F35: 499 | G35: 45323 | H35: 31 | I35: =IF(H35<=1,"Low",IF(H35<=4,"Medium","High")) -> High | J35: 15 | K35: =IF(J35<=1,"Low",IF(J35=2,"Medium","High")) -> High | L35: =IF(OR(I35="High",K35="High"),"High", IF(OR(I35="Medium",K35="Medium"),"Medium", "Low")) -> High | M35: =IF(AND(TRIM(I35)="High",TRIM(L35)="Low"),"Yes","No") -> No
A36: U035 | B36: Monthly | C36: 45331 | D36: 45360 | E36: 45350 | F36: 499 | G36: 45323 | H36: 45 | I36: =IF(H36<=1,"Low",IF(H36<=4,"Medium","High")) -> High | J36: 17 | K36: =IF(J36<=1,"Low",IF(J36=2,"Medium","High")) -> High | L36: =IF(OR(I36="High",K36="High"),"High", IF(OR(I36="Medium",K36="Medium"),"Medium", "Low")) -> High | M36: =IF(AND(TRIM(I36)="High",TRIM(L36)="Low"),"Yes","No") -> No
A37: U036 | B37: Annual | C37: 45332 | D37: 45698 | F37: 3999 | G37: 45323 | H37: 5 | I37: =IF(H37<=1,"Low",IF(H37<=4,"Medium","High")) -> High | J37: 5 | K37: =IF(J37<=1,"Low",IF(J37=2,"Medium","High")) -> High | L37: =IF(OR(I37="High",K37="High"),"High", IF(OR(I37="Medium",K37="Medium"),"Medium", "Low")) -> High | M37: =IF(AND(TRIM(I37)="High",TRIM(L37)="Low"),"Yes","No") -> No
A38: U037 | B38: Monthly | C38: 45333 | D38: 45362 | F38: 499 | G38: 45323 | H38: 4 | I38: =IF(H38<=1,"Low",IF(H38<=4,"Medium","High")) -> Medium | J38: 4 | K38: =IF(J38<=1,"Low",IF(J38=2,"Medium","High")) -> High | L38: =IF(OR(I38="High",K38="High"),"High", IF(OR(I38="Medium",K38="Medium"),"Medium", "Low")) -> High | M38: =IF(AND(TRIM(I38)="High",TRIM(L38)="Low"),"Yes","No") -> No
A39: U038 | B39: Monthly | C39: 45334 | D39: 45363 | E39: 45353 | F39: 499 | G39: 45323 | H39: 34 | I39: =IF(H39<=1,"Low",IF(H39<=4,"Medium","High")) -> High | J39: 14 | K39: =IF(J39<=1,"Low",IF(J39=2,"Medium","High")) -> High | L39: =IF(OR(I39="High",K39="High"),"High", IF(OR(I39="Medium",K39="Medium"),"Medium", "Low")) -> High | M39: =IF(AND(TRIM(I39)="High",TRIM(L39)="Low"),"Yes","No") -> No
A40: U039 | B40: Annual | C40: 45335 | D40: 45701 | F40: 3999 | G40: 45323 | H40: 28 | I40: =IF(H40<=1,"Low",IF(H40<=4,"Medium","High")) -> High | J40: 16 | K40: =IF(J40<=1,"Low",IF(J40=2,"Medium","High")) -> High | L40: =IF(OR(I40="High",K40="High"),"High", IF(OR(I40="Medium",K40="Medium"),"Medium", "Low")) -> High | M40: =IF(AND(TRIM(I40)="High",TRIM(L40)="Low"),"Yes","No") -> No
...
